<?xml version="1.0" ?>
<robot name="FlyingDeltaArmBase">



  <link name="base_link"/>
  <joint name="base" type="fixed">
    <parent link="base_link"/>
    <child link="FlyingDeltaArmBase__base_link1"/>
    <axis xyz="0 0 0"/>
    <origin rpy="0 0 0" xyz="0 0 0"/>
  </joint>



  <joint name="FlyingDeltaArmBase__rotor_0_joint" type="fixed">
    <parent link="FlyingDeltaArmBase__base_link1"/>
    <child link="FlyingDeltaArmBase__rotor_0"/>
    <origin rpy="0  0  0" xyz="0.2224  -0.22408  0.07"/>
    <axis xyz="0  0  0"/>
  </joint>

  <joint name="FlyingDeltaArmBase__rotor_1_joint" type="fixed">
    <parent link="FlyingDeltaArmBase__base_link1"/>
    <child link="FlyingDeltaArmBase__rotor_1"/>
    <origin rpy="0  0  0" xyz="-0.22408  0.22408  0.07"/>
    <axis xyz="0  0  0"/>
  </joint>

  <joint name="FlyingDeltaArmBase__rotor_2_joint" type="fixed">
    <parent link="FlyingDeltaArmBase__base_link1"/>
    <child link="FlyingDeltaArmBase__rotor_2"/>
    <origin rpy="0  0  0" xyz="0.22408  0.22408  0.07"/>
    <axis xyz="0  0  0"/>
  </joint>

  <joint name="FlyingDeltaArmBase__rotor_3_joint" type="fixed">
    <parent link="FlyingDeltaArmBase__base_link1"/>
    <child link="FlyingDeltaArmBase__rotor_3"/>
    <origin rpy="0  0  0" xyz="-0.22408 -0.22408  0.07"/>
    <axis xyz="0  0  0"/>
  </joint>
  <joint name="FlyingDeltaArmBase__link_0_JOINT_1" type="revolute">
    <parent link="FlyingDeltaArmBase__link_0"/>
    <child link="FlyingDeltaArmBase__uleg_1"/>
    <origin rpy="1.1  0   0" xyz="0     -0.1    -0.1125"/>
    <axis xyz="1  0  0"/>
    <limit effort="20.0" lower="-10.0" upper="10.0" velocity="1.0"/>
  </joint>
  <joint name="FlyingDeltaArmBase__link_0_JOINT_2" type="revolute">
    <parent link="FlyingDeltaArmBase__link_0"/>
    <child link="FlyingDeltaArmBase__uleg_2"/>
    <origin rpy="1.1      0      -2.09439" xyz="-0.0866  0.05   -0.1125"/>
    <axis xyz="1  0  0"/>
    <limit effort="20.0" lower="-10.0" upper="10.0" velocity="1.0"/>
  </joint>
  <joint name="FlyingDeltaArmBase__link_0_JOINT_3" type="revolute">
    <parent link="FlyingDeltaArmBase__link_0"/>
    <child link="FlyingDeltaArmBase__uleg_3"/>
    <origin rpy="1.1      0       2.09439" xyz="0.0866  0.05   -0.1125"/>
    <axis xyz="1  0  0"/>
    <limit effort="20.0" lower="-10.0" upper="10.0" velocity="1.0"/>
  </joint>
  <joint name="FlyingDeltaArmBase__Mbase" type="fixed">
    <child link="FlyingDeltaArmBase__link_0"/>
    <parent link="FlyingDeltaArmBase__base_link1"/>
    <origin rpy="0  0  0" xyz="0  0  0"/>
    <axis xyz="0  0  0"/>
    <limit effort="0" lower="0" upper="0" velocity="0"/>
  </joint>


  <link name="FlyingDeltaArmBase__base_link1">
    <inertial>
      <mass value="1.5"/>
      <origin rpy="0  0  0" xyz="0  0  0"/>
      <inertia ixx="0.1165" ixy="0" ixz="0" iyy="0.1165" iyz="0" izz="0.2209"/>
    </inertial>
    <collision name="FlyingDeltaArmBase__base_link1_inertia_collision">
      <origin rpy="0  0  0" xyz="0  0  0"/>
      <geometry>
        <box size="0.6 0.6 0.11"/>
      </geometry>
    </collision>
    <visual name="FlyingDeltaArmBase__base_link1_inertia_visual">
      <origin rpy="0  0  0" xyz="-0.272 -0.272 -0.16"/>
      <geometry>
        <mesh filename="$(find rviz_package)/meshes/up_base2.STL" scale="0.001 0.001 0.001"/>
      </geometry>
    </visual>
  </link>



  <link name="FlyingDeltaArmBase__rotor_0">
    <inertial>
      <mass value="0.005"/>
      <origin rpy="0  0  0" xyz="0  0  0"/>
      <inertia ixx="3.9e-06" ixy="0" ixz="0" iyy="0.001092416" iyz="0" izz="0.001096016"/>
    </inertial>
    <collision name="FlyingDeltaArmBase__rotor_0_collision">
      <origin rpy="0  0  0" xyz="0  0  0"/>
      <geometry>
        <cylinder length="0.0075" radius="0.192"/>
      </geometry>
    </collision>
    <visual name="FlyingDeltaArmBase__rotor_0_visual">
      <origin rpy="0  0  0" xyz="0  0  0"/>
      <geometry>
        <mesh filename="$(find rviz_package)/meshes/iris_prop_ccw.dae" scale="1.5 1.5 1.5"/>
      </geometry>
    </visual>
  </link>
  <link name="FlyingDeltaArmBase__rotor_1">
    <inertial>
      <mass value="0.005"/>
      <origin rpy="0  0  0" xyz="0  0  0"/>
      <inertia ixx="3.9e-06" ixy="0" ixz="0" iyy="0.001092416" iyz="0" izz="0.001096016"/>
    </inertial>
    <collision name="FlyingDeltaArmBase__rotor_1_collision">
      <origin rpy="0  0  0" xyz="0  0  0"/>
      <geometry>
        <cylinder length="0.0075" radius="0.192"/>
      </geometry>
    </collision>
    <visual name="FlyingDeltaArmBase__rotor_1_visual">
      <origin rpy="0  0  0" xyz="0  0  0"/>
      <geometry>
        <mesh filename="$(find rviz_package)/meshes/iris_prop_ccw.dae" scale="1.5 1.5 1.5"/>
      </geometry>
    </visual>
  </link>
  <link name="FlyingDeltaArmBase__rotor_2">
    <inertial>
      <mass value="0.005"/>
      <origin rpy="0  0  0" xyz="0  0  0"/>
      <inertia ixx="3.9e-06" ixy="0" ixz="0" iyy="0.001092416" iyz="0" izz="0.001096016"/>
    </inertial>
    <collision name="FlyingDeltaArmBase__rotor_2_collision">
      <origin rpy="0  0  0" xyz="0  0  0"/>
      <geometry>
        <cylinder length="0.0075" radius="0.192"/>
      </geometry>
    </collision>
    <visual name="FlyingDeltaArmBase__rotor_2_visual">
      <origin rpy="0  0  0" xyz="0  0  0"/>
      <geometry>
        <mesh filename="$(find rviz_package)/meshes/iris_prop_cw.dae" scale="1.5 1.5 1.5"/>
      </geometry>
    </visual>
  </link>
  <link name="FlyingDeltaArmBase__rotor_3">
    <inertial>
      <mass value="0.005"/>
      <origin rpy="0  0  0" xyz="0  0  0"/>
      <inertia ixx="3.9e-06" ixy="0" ixz="0" iyy="0.001092416" iyz="0" izz="0.001096016"/>
    </inertial>
    <collision name="FlyingDeltaArmBase__rotor_3_collision">
      <origin rpy="0  0  0" xyz="0  0  0"/>
      <geometry>
        <cylinder length="0.0075" radius="0.192"/>
      </geometry>
    </collision>
    <visual name="FlyingDeltaArmBase__rotor_3_visual">
      <origin rpy="0  0  0" xyz="0  0  0"/>
      <geometry>
        <mesh filename="$(find rviz_package)/meshes/iris_prop_cw.dae" scale="1.5 1.5 1.5"/>
      </geometry>
    </visual>
  </link>
  <link name="FlyingDeltaArmBase__link_0">
    <inertial>
      <mass value="0.48"/>
      <origin rpy="0  0  0" xyz="0  0  0"/>
      <inertia ixx="0.000452" ixy="0" ixz="0" iyy="0.000452" iyz="0" izz="0.000392"/>
    </inertial>
    <collision name="FlyingDeltaArmBase__link_0_collision">
      <origin rpy="0  0  0" xyz="0     0    -0.097"/>
      <geometry>
        <box size="0.07 0.07 0.08"/>
      </geometry>
    </collision>
    <visual name="FlyingDeltaArmBase__link_0_visual">
      <origin rpy="0  0  0" xyz="-0.1065 -0.117  -0.162"/>
      <geometry>
        <mesh filename="$(find rviz_package)/meshes/base_low.STL" scale="0.001 0.001 0.001"/>
      </geometry>
    </visual>
  </link>
  <link name="FlyingDeltaArmBase__uleg_1">
    <inertial>
      <mass value="0.0466"/>
      <origin rpy="0  0  0" xyz="0  0  0"/>
      <inertia ixx="5.630833e-05" ixy="0" ixz="0" iyy="2.796e-06" iyz="0" izz="5.4630733e-05"/>
    </inertial>
    <collision name="FlyingDeltaArmBase__uleg_1_collision">
      <origin rpy="0       0      -2.09439" xyz="-0.00869  0.03    -0.05"/>
      <geometry>
        <mesh filename="$(find rviz_package)/meshes/arm.STL" scale="0.001 0.001 0.001"/>
      </geometry>
    </collision>
    <visual name="FlyingDeltaArmBase__uleg_1_visual">
      <origin rpy="0       0      -2.09439" xyz="-0.00869  0.03    -0.05"/>
      <geometry>
        <mesh filename="$(find rviz_package)/meshes/arm.STL" scale="0.001 0.001 0.001"/>
      </geometry>
    </visual>
  </link>
  <link name="FlyingDeltaArmBase__uleg_2">
    <inertial>
      <mass value="0.0466"/>
      <origin rpy="0  0  0" xyz="0  0  0"/>
      <inertia ixx="5.630833e-05" ixy="0" ixz="0" iyy="2.796e-06" iyz="0" izz="5.4630733e-05"/>
    </inertial>
    <collision name="FlyingDeltaArmBase__uleg_2_collision">
      <origin rpy="0       0      -2.09439" xyz="-0.00869  0.03    -0.05"/>
      <geometry>
        <mesh filename="$(find rviz_package)/meshes/arm.STL" scale="0.001 0.001 0.001"/>
      </geometry>
    </collision>
    <visual name="FlyingDeltaArmBase__uleg_2_visual">
      <origin rpy="0       0      -2.09439" xyz="-0.00869  0.03    -0.05"/>
      <geometry>
        <mesh filename="$(find rviz_package)/meshes/arm.STL" scale="0.001 0.001 0.001"/>
      </geometry>
    </visual>
  </link>
  <link name="FlyingDeltaArmBase__uleg_3">
    <inertial>
      <mass value="0.0466"/>
      <origin rpy="0  0  0" xyz="0  0  0"/>
      <inertia ixx="5.630833e-05" ixy="0" ixz="0" iyy="2.796e-06" iyz="0" izz="5.4630733e-05"/>
    </inertial>
    <collision name="FlyingDeltaArmBase__uleg_3_collision">
      <origin rpy="0       0      -2.09439" xyz="-0.00869  0.03    -0.05"/>
      <geometry>
        <mesh filename="$(find rviz_package)/meshes/arm.STL" scale="0.001 0.001 0.001"/>
      </geometry>
    </collision>
    <visual name="FlyingDeltaArmBase__uleg_3_visual">
      <origin rpy="0       0      -2.09439" xyz="-0.00869  0.03    -0.05"/>
      <geometry>
        <mesh filename="$(find rviz_package)/meshes/arm.STL" scale="0.001 0.001 0.001"/>
      </geometry>
    </visual>
  </link>



  <link name="FlyingDeltaArmBase__low_base">
    <inertial>
      <mass value="0.03"/>
      <origin rpy="0  0  0" xyz="-0.03  0.03  0"/>
      <inertia ixx="4.5e-06" ixy="0" ixz="0" iyy="4.5e-06" iyz="0" izz="4.5e-06"/>
    </inertial>
    <visual name="FlyingDeltaArmBase__low_base_visual_visual">
      <origin rpy="0  0  0" xyz="-0.04    -0.03599 0"/>
      <geometry>
        <mesh filename="$(find rviz_package)/meshes/Platform.STL" scale="0.001 0.001 0.001"/>
      </geometry>
    </visual>
  </link>

  <joint name="baseFloating" type="fixed">
    <parent link="FlyingDeltaArmBase__base_link1"/>
    <child link="FlyingDeltaArmBase__low_base"/>
    <origin rpy="0  0  0" xyz="0 0 0"/>
    <axis xyz="0  0  0"/>
  </joint>

</robot>
